Creating instance of Random Forest model...
Fitting model...
Evaluating model...
Model accuracy before any fine-tuning is: 0.7706725468577729
Running grid search cv...
> /Users/kelseydoerksen/code/giga-connectivity/classifiers/rf.py(152)run_rf()
    151
--> 152         best_forest = grid_search.best_estimator_
    153
RandomForestClassifier(max_depth=80, max_features=4, min_samples_leaf=5,
                       min_samples_split=4, n_estimators=500, n_jobs=-1,
                       random_state=87)
*** NameError: name 'best_forest' is not defined
0.8353474320241693
GridSearchCV(cv=5,
             estimator=RandomForestClassifier(n_estimators=200, n_jobs=-1,
                                              random_state=87),
             n_jobs=-1,
             param_grid={'bootstrap': [True], 'max_depth': [80, 90, 100],
                         'max_features': [2, 3, 4],
                         'min_samples_leaf': [3, 4, 5],
                         'min_samples_split': [4, 6, 8],
                         'n_estimators': [100, 200, 300, 500]},
             refit='f1', scoring={'recall', 'precision', 'f1', 'accuracy'})
*** AttributeError: 'GridSearchCV' object has no attribute 'accuracy'
{'recall', 'precision', 'f1', 'accuracy'}
*** AttributeError: 'set' object has no attribute 'accuracy'
Traceback (most recent call last):
  File "/Users/kelseydoerksen/code/giga-connectivity/run_pipeline.py", line 412, in <module>
    rf.run_rf(
  File "/Users/kelseydoerksen/code/giga-connectivity/classifiers/rf.py", line 152, in run_rf
    best_forest = rf_cv.best_estimator_
  File "/Users/kelseydoerksen/code/giga-connectivity/classifiers/rf.py", line 152, in run_rf
    best_forest = rf_cv.best_estimator_
  File "/Users/kelseydoerksen/opt/anaconda3/envs/giga/lib/python3.10/bdb.py", line 90, in trace_dispatch
    return self.dispatch_line(frame)
  File "/Users/kelseydoerksen/opt/anaconda3/envs/giga/lib/python3.10/bdb.py", line 115, in dispatch_line
    if self.quitting: raise BdbQuit
bdb.BdbQuit
If you suspect this is an IPython 8.7.0 bug, please report it at:
    https://github.com/ipython/ipython/issues
or send an email to the mailing list at ipython-dev@python.org
You can print a more detailed traceback right now with "%tb", or use "%debug"
to interactively debug it.
Extra-detailed tracebacks for bug-reporting purposes can be enabled via:
    %config Application.verbose_crash=True