> /Users/kelseydoerksen/code/giga-connectivity/run_pipeline.py(101)load_data()
    100
--> 101     training_dataset = shuffle(training_data)
    102     testing_dataset = shuffle(testing_data)
*** NameError: name 'training_dataset' is not defined
     Unnamed: 0         0  ...                        giga_id_school  connectivity
0             0 -0.415606  ...  e0362b14-76fd-3ffb-a503-4c9d4a0a7df0           1.0
1             1 -0.630196  ...  b43f3288-bf2a-3f46-885e-c34edb3fdc50           1.0
2             2 -0.972825  ...  e760effc-dc5b-3fe6-8f7f-07ef93185b84           1.0
3             3 -0.594224  ...  98d7f916-52a2-3522-864f-491394c87cd5           1.0
4             4 -0.367657  ...  b02bd5f2-ea9b-364e-9068-923f4e522b1b           1.0
..          ...       ...  ...                                   ...           ...
629         629 -0.575585  ...  7b2a9b91-dba3-34d8-9333-24038c945c3b           0.0
630         630 -0.723753  ...  19d077c6-af1c-32e1-92c6-8150454312d4           1.0
631         631 -0.600073  ...  80a62c7e-031f-35dd-a1f3-6147a491a694           0.0
632         632 -1.002936  ...  2e69ea33-5748-3496-99d6-0bc0a8d2f86a           0.0
633         633 -0.544151  ...  d6256f86-6e62-3f9c-8f18-425152e4d8bf           0.0
[634 rows x 1029 columns]
Index(['Unnamed: 0', '0', '1', '2', '3', '4', '5', '6', '7', '8',
       ...
       '1018', '1019', '1020', '1021', '1022', '1023', 'fid', 'location',
       'giga_id_school', 'connectivity'],
      dtype='object', length=1029)
Traceback (most recent call last):
  File "/Users/kelseydoerksen/code/giga-connectivity/run_pipeline.py", line 186, in <module>
    train_data, test_data = load_data(aoi, buffer, features)
  File "/Users/kelseydoerksen/code/giga-connectivity/run_pipeline.py", line 101, in load_data
    training_dataset = shuffle(training_data)
  File "/Users/kelseydoerksen/code/giga-connectivity/run_pipeline.py", line 101, in load_data
    training_dataset = shuffle(training_data)
  File "/Users/kelseydoerksen/opt/anaconda3/envs/giga/lib/python3.10/bdb.py", line 90, in trace_dispatch
    return self.dispatch_line(frame)
  File "/Users/kelseydoerksen/opt/anaconda3/envs/giga/lib/python3.10/bdb.py", line 115, in dispatch_line
    if self.quitting: raise BdbQuit
bdb.BdbQuit
If you suspect this is an IPython 8.7.0 bug, please report it at:
    https://github.com/ipython/ipython/issues
or send an email to the mailing list at ipython-dev@python.org
You can print a more detailed traceback right now with "%tb", or use "%debug"
to interactively debug it.
Extra-detailed tracebacks for bug-reporting purposes can be enabled via:
    %config Application.verbose_crash=True