Traceback (most recent call last):
  File "/Users/kelseydoerksen/code/giga-connectivity/run_pipeline.py", line 174, in <module>
    train_data, test_data = load_data(aoi, buffer, features)
  File "/Users/kelseydoerksen/code/giga-connectivity/run_pipeline.py", line 77, in load_data
    training_data = training_data.drop(columns=['Unnamed: 0', 'Unnamed: 0.1', 'connectivity.1', 'index'])
  File "/Users/kelseydoerksen/opt/anaconda3/envs/giga/lib/python3.10/site-packages/pandas/util/_decorators.py", line 331, in wrapper
    return func(*args, **kwargs)
  File "/Users/kelseydoerksen/opt/anaconda3/envs/giga/lib/python3.10/site-packages/pandas/core/frame.py", line 5396, in drop
    return super().drop(
  File "/Users/kelseydoerksen/opt/anaconda3/envs/giga/lib/python3.10/site-packages/pandas/util/_decorators.py", line 331, in wrapper
    return func(*args, **kwargs)
  File "/Users/kelseydoerksen/opt/anaconda3/envs/giga/lib/python3.10/site-packages/pandas/core/generic.py", line 4505, in drop
    obj = obj._drop_axis(labels, axis, level=level, errors=errors)
  File "/Users/kelseydoerksen/opt/anaconda3/envs/giga/lib/python3.10/site-packages/pandas/core/generic.py", line 4575, in _drop_axis
    raise KeyError(f"{labels} not found in axis")
KeyError: "['Unnamed: 0' 'Unnamed: 0.1' 'connectivity.1' 'index'] not found in axis"