> /Users/kelseydoerksen/code/giga-connectivity/run_pipeline.py(85)load_data()
     84
---> 85         train_df = merge_train.drop(columns=['UID', 'class_y'])
     86         test_df = merge_test.drop(columns=['UID', 'class_y'])
*** NameError: name 'train_df' is not defined
Index(['Unnamed: 0', 'UID', 'lat', 'lon', 'class_x', 'modis.LC_Type1.mode',
       'modis.LC_Type1.var', 'modis.LC_Type1.evg_conif',
       'modis.LC_Type1.evg_broad', 'modis.LC_Type1.dcd_needle',
       ...
       '378', '379', '380', '381', '382', '383', 'iso', 'rurban', 'dataset',
       'class_y'],
      dtype='object', length=448)
0        test
1       train
2       train
3       train
4       train
        ...
1819    train
1820    train
1821    train
1822    train
1823    train
Name: dataset, Length: 1824, dtype: object
0       BWA
1       BWA
2       BWA
3       BWA
4       BWA
       ...
1819    BWA
1820    BWA
1821    BWA
1822    BWA
1823    BWA
Name: iso, Length: 1824, dtype: object
Index(['Unnamed: 0', 'lat', 'lon', 'class_x', 'modis.LC_Type1.mode',
       'modis.LC_Type1.var', 'modis.LC_Type1.evg_conif',
       'modis.LC_Type1.evg_broad', 'modis.LC_Type1.dcd_needle',
       'modis.LC_Type1.dcd_broad',
       ...
       '374', '375', '376', '377', '378', '379', '380', '381', '382', '383'],
      dtype='object', length=443)
Index(['lat', 'lon', 'class_x', 'modis.LC_Type1.mode', 'modis.LC_Type1.var',
       'modis.LC_Type1.evg_conif', 'modis.LC_Type1.evg_broad',
       'modis.LC_Type1.dcd_needle', 'modis.LC_Type1.dcd_broad',
       'modis.LC_Type1.mix_forest',
       ...
       '374', '375', '376', '377', '378', '379', '380', '381', '382', '383'],
      dtype='object', length=442)
Traceback (most recent call last):
  File "/Users/kelseydoerksen/code/giga-connectivity/run_pipeline.py", line 279, in <module>
    train_data, test_data = load_data(aoi, buffer, features, label)
  File "/Users/kelseydoerksen/code/giga-connectivity/run_pipeline.py", line 85, in load_data
    train_df = merge_train.drop(columns=['UID', 'class_y', 'dataset', 'iso', 'rurban', 'Unnamed: 0'])
  File "/Users/kelseydoerksen/code/giga-connectivity/run_pipeline.py", line 85, in load_data
    train_df = merge_train.drop(columns=['UID', 'class_y', 'dataset', 'iso', 'rurban', 'Unnamed: 0'])
  File "/Users/kelseydoerksen/opt/anaconda3/envs/giga/lib/python3.10/bdb.py", line 90, in trace_dispatch
    return self.dispatch_line(frame)
  File "/Users/kelseydoerksen/opt/anaconda3/envs/giga/lib/python3.10/bdb.py", line 115, in dispatch_line
    if self.quitting: raise BdbQuit
bdb.BdbQuit
If you suspect this is an IPython 8.7.0 bug, please report it at:
    https://github.com/ipython/ipython/issues
or send an email to the mailing list at ipython-dev@python.org
You can print a more detailed traceback right now with "%tb", or use "%debug"
to interactively debug it.
Extra-detailed tracebacks for bug-reporting purposes can be enabled via:
    %config Application.verbose_crash=True