Creating instance of GB model...
Fitting data...
The hard predictions were right 71.79% of the time
No model hyperparameter tuning
> /Users/kelseydoerksen/code/giga-connectivity/classifiers/gb.py(58)run_gb()
     57         # Saving results for further plotting
---> 58         results_for_plotting(y_test, probs, test_latitudes, test_longitudes, results_dir, model_name)
     59
'/Users/kelseydoerksen/Desktop/Giga/BWA/results_1000m/hopeful-plant-543'
Traceback (most recent call last):
  File "/Users/kelseydoerksen/code/giga-connectivity/run_pipeline.py", line 296, in <module>
    gb.run_gb(
  File "/Users/kelseydoerksen/code/giga-connectivity/classifiers/gb.py", line 58, in run_gb
    results_for_plotting(y_test, probs, test_latitudes, test_longitudes, results_dir, model_name)
  File "/Users/kelseydoerksen/code/giga-connectivity/classifiers/gb.py", line 58, in run_gb
    results_for_plotting(y_test, probs, test_latitudes, test_longitudes, results_dir, model_name)
  File "/Users/kelseydoerksen/opt/anaconda3/envs/giga/lib/python3.10/bdb.py", line 90, in trace_dispatch
    return self.dispatch_line(frame)
  File "/Users/kelseydoerksen/opt/anaconda3/envs/giga/lib/python3.10/bdb.py", line 115, in dispatch_line
    if self.quitting: raise BdbQuit
bdb.BdbQuit
If you suspect this is an IPython 8.7.0 bug, please report it at:
    https://github.com/ipython/ipython/issues
or send an email to the mailing list at ipython-dev@python.org
You can print a more detailed traceback right now with "%tb", or use "%debug"
to interactively debug it.
Extra-detailed tracebacks for bug-reporting purposes can be enabled via:
    %config Application.verbose_crash=True