Creating instance of Random Forest model...
Fitting model...
Evaluating model...
The hard predictions were right 82.05% of the time
Running grid search cv...
> /Users/kelseydoerksen/code/giga-connectivity/classifiers/rf.py(115)run_rf()
    114     ipdb.set_trace()
--> 115     grid_search.best_params_
    116
{'bootstrap': True, 'max_depth': 80, 'max_features': 4, 'min_samples_leaf': 3, 'min_samples_split': 4, 'n_estimators': 100}
RandomForestClassifier(max_depth=80, max_features=4, min_samples_leaf=3,
                       min_samples_split=4, n_jobs=-1, random_state=87)
*** KeyError: 'f1'
{'fit_time': array([3.93359208, 0.10574603, 0.10311103, 0.10493612, 0.10607505]), 'score_time': array([0.02412915, 0.02024221, 0.02038074, 0.01956582, 0.01969504]), 'test_accuracy': array([0.81818182, 0.63636364, 0.72727273, 0.7962963 , 0.66666667]), 'test_f1': array([0.84375   , 0.64285714, 0.72727273, 0.79245283, 0.66666667])}
0.7345998733970431
0.7470325497376201
Traceback (most recent call last):
  File "/Users/kelseydoerksen/code/giga-connectivity/run_pipeline.py", line 117, in <module>
    rf.run_rf(
  File "/Users/kelseydoerksen/code/giga-connectivity/classifiers/rf.py", line 115, in run_rf
  File "/Users/kelseydoerksen/code/giga-connectivity/classifiers/rf.py", line 115, in run_rf
  File "/Users/kelseydoerksen/opt/anaconda3/envs/giga/lib/python3.10/bdb.py", line 90, in trace_dispatch
    return self.dispatch_line(frame)
  File "/Users/kelseydoerksen/opt/anaconda3/envs/giga/lib/python3.10/bdb.py", line 115, in dispatch_line
    if self.quitting: raise BdbQuit
bdb.BdbQuit
If you suspect this is an IPython 8.7.0 bug, please report it at:
    https://github.com/ipython/ipython/issues
or send an email to the mailing list at ipython-dev@python.org
You can print a more detailed traceback right now with "%tb", or use "%debug"
to interactively debug it.
Extra-detailed tracebacks for bug-reporting purposes can be enabled via:
    %config Application.verbose_crash=True