Traceback (most recent call last):
  File "/Users/kelseydoerksen/code/giga-connectivity/run_pipeline.py", line 174, in <module>
    train_data, test_data = load_data(aoi, buffer, features)
  File "/Users/kelseydoerksen/code/giga-connectivity/run_pipeline.py", line 62, in load_data
    emb_test_df = emb_test_df.drop(columns=['connectivity, Unnamed: 0'])
  File "/Users/kelseydoerksen/opt/anaconda3/envs/giga/lib/python3.10/site-packages/pandas/util/_decorators.py", line 331, in wrapper
    return func(*args, **kwargs)
  File "/Users/kelseydoerksen/opt/anaconda3/envs/giga/lib/python3.10/site-packages/pandas/core/frame.py", line 5396, in drop
    return super().drop(
  File "/Users/kelseydoerksen/opt/anaconda3/envs/giga/lib/python3.10/site-packages/pandas/util/_decorators.py", line 331, in wrapper
    return func(*args, **kwargs)
  File "/Users/kelseydoerksen/opt/anaconda3/envs/giga/lib/python3.10/site-packages/pandas/core/generic.py", line 4505, in drop
    obj = obj._drop_axis(labels, axis, level=level, errors=errors)
  File "/Users/kelseydoerksen/opt/anaconda3/envs/giga/lib/python3.10/site-packages/pandas/core/generic.py", line 4546, in _drop_axis
    new_axis = axis.drop(labels, errors=errors)
  File "/Users/kelseydoerksen/opt/anaconda3/envs/giga/lib/python3.10/site-packages/pandas/core/indexes/base.py", line 6977, in drop
    raise KeyError(f"{list(labels[mask])} not found in axis")
KeyError: "['connectivity, Unnamed: 0'] not found in axis"