> /Users/kelseydoerksen/code/giga-connectivity/run_pipeline.py(103)load_data()
    102
--> 103     training_dataset = shuffle(training_data)
    104     testing_dataset = shuffle(testing_data)
*** NameError: name 'trainin_data' is not defined
Index(['Unnamed: 0', '0', '1', '2', '3', '4', '5', '6', '7', '8',
       ...
       '504', '505', '506', '507', '508', '509', '510', '511', 'location',
       'connectivity'],
      dtype='object', length=515)
Index(['Unnamed: 0', '0', '1', '2', '3', '4', '5', '6', '7', '8',
       ...
       '248', '249', '250', '251', '252', '253', '254', '255', 'location',
       'connectivity'],
      dtype='object', length=259)
Traceback (most recent call last):
  File "/Users/kelseydoerksen/code/giga-connectivity/run_pipeline.py", line 187, in <module>
    train_data, test_data = load_data(aoi, buffer, features)
  File "/Users/kelseydoerksen/code/giga-connectivity/run_pipeline.py", line 103, in load_data
    training_dataset = shuffle(training_data)
  File "/Users/kelseydoerksen/code/giga-connectivity/run_pipeline.py", line 103, in load_data
    training_dataset = shuffle(training_data)
  File "/Users/kelseydoerksen/opt/anaconda3/envs/giga/lib/python3.10/bdb.py", line 90, in trace_dispatch
    return self.dispatch_line(frame)
  File "/Users/kelseydoerksen/opt/anaconda3/envs/giga/lib/python3.10/bdb.py", line 115, in dispatch_line
    if self.quitting: raise BdbQuit
bdb.BdbQuit
If you suspect this is an IPython 8.7.0 bug, please report it at:
    https://github.com/ipython/ipython/issues
or send an email to the mailing list at ipython-dev@python.org
You can print a more detailed traceback right now with "%tb", or use "%debug"
to interactively debug it.
Extra-detailed tracebacks for bug-reporting purposes can be enabled via:
    %config Application.verbose_crash=True