Scaling data...
Creating instance of MLP model...
Fitting data...
The hard predictions were right 61.90% of the time
Running grid search cv...
Traceback (most recent call last):
  File "/Users/kelseydoerksen/code/giga-connectivity/run_pipeline.py", line 207, in <module>
    mlp.run_mlp(
  File "/Users/kelseydoerksen/code/giga-connectivity/classifiers/mlp.py", line 63, in run_mlp
    results_for_plotting(y_test, probs, test_latitudes, test_longitudes, results_dir, model_name)
  File "/Users/kelseydoerksen/code/giga-connectivity/analysis/generating_results.py", line 28, in results_for_plotting
    df_results['lat'] = latitudes
  File "/Users/kelseydoerksen/opt/anaconda3/envs/giga/lib/python3.10/site-packages/pandas/core/frame.py", line 3978, in __setitem__
    self._set_item(key, value)
  File "/Users/kelseydoerksen/opt/anaconda3/envs/giga/lib/python3.10/site-packages/pandas/core/frame.py", line 4172, in _set_item
    value = self._sanitize_column(value)
  File "/Users/kelseydoerksen/opt/anaconda3/envs/giga/lib/python3.10/site-packages/pandas/core/frame.py", line 4912, in _sanitize_column
    com.require_length_match(value, self.index)
  File "/Users/kelseydoerksen/opt/anaconda3/envs/giga/lib/python3.10/site-packages/pandas/core/common.py", line 561, in require_length_match
    raise ValueError(
ValueError: Length of values (0) does not match length of index (273)