Traceback (most recent call last):
  File "/Users/kelseydoerksen/opt/anaconda3/envs/giga/lib/python3.10/site-packages/pandas/core/indexes/base.py", line 3803, in get_loc
    return self._engine.get_loc(casted_key)
  File "pandas/_libs/index.pyx", line 138, in pandas._libs.index.IndexEngine.get_loc
  File "pandas/_libs/index.pyx", line 165, in pandas._libs.index.IndexEngine.get_loc
  File "pandas/_libs/hashtable_class_helper.pxi", line 5745, in pandas._libs.hashtable.PyObjectHashTable.get_item
  File "pandas/_libs/hashtable_class_helper.pxi", line 5753, in pandas._libs.hashtable.PyObjectHashTable.get_item
KeyError: 'label'
The above exception was the direct cause of the following exception:
Traceback (most recent call last):
  File "/Users/kelseydoerksen/code/giga-connectivity/run_pipeline.py", line 345, in <module>
    get_class_balance(train_data, test_data, results)
  File "/Users/kelseydoerksen/code/giga-connectivity/run_pipeline.py", line 242, in get_class_balance
    positive_samples_total = sum(train_df['label']) + sum(test_df['label'])
  File "/Users/kelseydoerksen/opt/anaconda3/envs/giga/lib/python3.10/site-packages/pandas/core/frame.py", line 3805, in __getitem__
    indexer = self.columns.get_loc(key)
  File "/Users/kelseydoerksen/opt/anaconda3/envs/giga/lib/python3.10/site-packages/pandas/core/indexes/base.py", line 3805, in get_loc
    raise KeyError(key) from err
KeyError: 'label'