Traceback (most recent call last):
  File "/Users/kelseydoerksen/code/giga-connectivity/run_pipeline.py", line 276, in <module>
    train_data, test_data = load_data(aoi, buffer, features, label)
  File "/Users/kelseydoerksen/code/giga-connectivity/run_pipeline.py", line 85, in load_data
    train_df = train_df.rename(columns={'class_x: label'})
  File "/Users/kelseydoerksen/opt/anaconda3/envs/giga/lib/python3.10/site-packages/pandas/core/frame.py", line 5570, in rename
    return super()._rename(
  File "/Users/kelseydoerksen/opt/anaconda3/envs/giga/lib/python3.10/site-packages/pandas/core/generic.py", line 1104, in _rename
    new_index = ax._transform_index(f, level=level)
  File "/Users/kelseydoerksen/opt/anaconda3/envs/giga/lib/python3.10/site-packages/pandas/core/indexes/base.py", line 6459, in _transform_index
    items = [func(x) for x in self]
  File "/Users/kelseydoerksen/opt/anaconda3/envs/giga/lib/python3.10/site-packages/pandas/core/indexes/base.py", line 6459, in <listcomp>
    items = [func(x) for x in self]
TypeError: 'set' object is not callable