Creating instance of MLP model...
Fitting data...
The hard predictions were right 55.68% of the time
> /Users/kelseydoerksen/code/giga-connectivity/classifiers/mlp.py(41)run_mlp()
     40     # CV scoring
---> 41     cv_scoring = cross_validate(clf, X_test, y_test, scoring=['accuracy', 'f1'], cv=5)
     42     print('Accuracy scores for each fold are: {}'.format(cv_scoring['test_accuracy']))
Traceback (most recent call last):
  File "/Users/kelseydoerksen/code/giga-connectivity/run_pipeline.py", line 150, in <module>
    mlp.run_mlp(
  File "/Users/kelseydoerksen/code/giga-connectivity/classifiers/mlp.py", line 41, in run_mlp
    cv_scoring = cross_validate(clf, X_test, y_test, scoring=['accuracy', 'f1'], cv=5)
  File "/Users/kelseydoerksen/code/giga-connectivity/classifiers/mlp.py", line 41, in run_mlp
    cv_scoring = cross_validate(clf, X_test, y_test, scoring=['accuracy', 'f1'], cv=5)
  File "/Users/kelseydoerksen/opt/anaconda3/envs/giga/lib/python3.10/bdb.py", line 90, in trace_dispatch
    return self.dispatch_line(frame)
  File "/Users/kelseydoerksen/opt/anaconda3/envs/giga/lib/python3.10/bdb.py", line 115, in dispatch_line
    if self.quitting: raise BdbQuit
bdb.BdbQuit
If you suspect this is an IPython 8.7.0 bug, please report it at:
    https://github.com/ipython/ipython/issues
or send an email to the mailing list at ipython-dev@python.org
You can print a more detailed traceback right now with "%tb", or use "%debug"
to interactively debug it.
Extra-detailed tracebacks for bug-reporting purposes can be enabled via:
    %config Application.verbose_crash=True