> /Users/kelseydoerksen/code/giga-connectivity/run_pipeline.py(190)<module>()
    189             ipdb.set_trace()
--> 190             lon = ast.literal_eval(test_data['location'].loc['{}'.format(i)])[0]
    191             lat = ast.literal_eval(test_data['location'].loc['{}'.format(i)])[1]
*** SyntaxError: invalid syntax
*** SyntaxError: invalid syntax
*** SyntaxError: invalid syntax
*** NameError: name 'test' is not defined
268   NaN
68    NaN
142   NaN
62    NaN
152   NaN
       ..
38    NaN
85    NaN
39    NaN
259   NaN
10    NaN
Name: location, Length: 273, dtype: float64
*** NameError: name 'test' is not defined
*** NameError: name 'test' is not defined
     location  connectivity
268       NaN           1.0
68        NaN           0.0
142       NaN           1.0
62        NaN           0.0
152       NaN           0.0
..        ...           ...
38        NaN           1.0
85        NaN           1.0
39        NaN           1.0
259       NaN           1.0
10        NaN           0.0
[273 rows x 2 columns]
Traceback (most recent call last):
  File "/Users/kelseydoerksen/code/giga-connectivity/run_pipeline.py", line 190, in <module>
    import ipdb
  File "/Users/kelseydoerksen/code/giga-connectivity/run_pipeline.py", line 190, in <module>
    import ipdb
  File "/Users/kelseydoerksen/opt/anaconda3/envs/giga/lib/python3.10/bdb.py", line 90, in trace_dispatch
    return self.dispatch_line(frame)
  File "/Users/kelseydoerksen/opt/anaconda3/envs/giga/lib/python3.10/bdb.py", line 115, in dispatch_line
    if self.quitting: raise BdbQuit
bdb.BdbQuit
If you suspect this is an IPython 8.7.0 bug, please report it at:
    https://github.com/ipython/ipython/issues
or send an email to the mailing list at ipython-dev@python.org
You can print a more detailed traceback right now with "%tb", or use "%debug"
to interactively debug it.
Extra-detailed tracebacks for bug-reporting purposes can be enabled via:
    %config Application.verbose_crash=True