Traceback (most recent call last):
  File "/Users/kelseydoerksen/opt/anaconda3/envs/giga/lib/python3.10/site-packages/pandas/core/indexes/base.py", line 3803, in get_loc
    return self._engine.get_loc(casted_key)
  File "pandas/_libs/index.pyx", line 138, in pandas._libs.index.IndexEngine.get_loc
  File "pandas/_libs/index.pyx", line 165, in pandas._libs.index.IndexEngine.get_loc
  File "pandas/_libs/hashtable_class_helper.pxi", line 5745, in pandas._libs.hashtable.PyObjectHashTable.get_item
  File "pandas/_libs/hashtable_class_helper.pxi", line 5753, in pandas._libs.hashtable.PyObjectHashTable.get_item
KeyError: False
The above exception was the direct cause of the following exception:
Traceback (most recent call last):
  File "/Users/kelseydoerksen/code/giga-connectivity/run_pipeline.py", line 314, in <module>
    train_data, test_data = load_schoolmapping_data(aoi, buffer, features, data_split)
  File "/Users/kelseydoerksen/code/giga-connectivity/run_pipeline.py", line 164, in load_schoolmapping_data
    train_df = mobility_df[mobility_df['dataset' == 'train']]
  File "/Users/kelseydoerksen/opt/anaconda3/envs/giga/lib/python3.10/site-packages/pandas/core/frame.py", line 3805, in __getitem__
    indexer = self.columns.get_loc(key)
  File "/Users/kelseydoerksen/opt/anaconda3/envs/giga/lib/python3.10/site-packages/pandas/core/indexes/base.py", line 3805, in get_loc
    raise KeyError(key) from err
KeyError: False