> /Users/kelseydoerksen/code/giga-connectivity/run_pipeline.py(66)load_data()
     65         ipdb.set_trace()
---> 66         training_data = train_df.drop(columns=['UID'])
     67         testing_data = test_df.drop(columns=['UID'])
*** NameError: name 'training_data' is not defined
Index(['Unnamed: 0.1', 'Unnamed: 0', 'UID', 'lat', 'lon', 'class', 'class.1',
       'weekday_var', 'weekday_peak_hour', 'weekday_measurement_count'],
      dtype='object')
Traceback (most recent call last):
  File "/Users/kelseydoerksen/code/giga-connectivity/run_pipeline.py", line 357, in <module>
    # Save data class balance breakdown
  File "/Users/kelseydoerksen/code/giga-connectivity/run_pipeline.py", line 66, in load_data
    training_data = training_data.rename(columns={'class': 'label'})
  File "/Users/kelseydoerksen/code/giga-connectivity/run_pipeline.py", line 66, in load_data
    training_data = training_data.rename(columns={'class': 'label'})
  File "/Users/kelseydoerksen/opt/anaconda3/envs/giga/lib/python3.10/bdb.py", line 90, in trace_dispatch
    return self.dispatch_line(frame)
  File "/Users/kelseydoerksen/opt/anaconda3/envs/giga/lib/python3.10/bdb.py", line 115, in dispatch_line
    if self.quitting: raise BdbQuit
bdb.BdbQuit
If you suspect this is an IPython 8.7.0 bug, please report it at:
    https://github.com/ipython/ipython/issues
or send an email to the mailing list at ipython-dev@python.org
You can print a more detailed traceback right now with "%tb", or use "%debug"
to interactively debug it.
Extra-detailed tracebacks for bug-reporting purposes can be enabled via:
    %config Application.verbose_crash=True