> /Users/kelseydoerksen/code/giga-connectivity/run_pipeline.py(125)load_data()
    124
--> 125     training_dataset = shuffle(training_data)
    126     testing_dataset = shuffle(testing_data)
Index(['Unnamed: 0', '0', '1', '2', '3', '4', '5', '6', '7', '8',
       ...
       '1019', '1020', '1021', '1022', '1023', 'giga_id_school', 'lat', 'lon',
       'connectivity', 'data_split'],
      dtype='object', length=1030)
Traceback (most recent call last):
  File "/Users/kelseydoerksen/code/giga-connectivity/run_pipeline.py", line 212, in <module>
    # Load data
  File "/Users/kelseydoerksen/code/giga-connectivity/run_pipeline.py", line 125, in load_data
    testing_dataset = shuffle(testing_data)
  File "/Users/kelseydoerksen/code/giga-connectivity/run_pipeline.py", line 125, in load_data
    testing_dataset = shuffle(testing_data)
  File "/Users/kelseydoerksen/opt/anaconda3/envs/giga/lib/python3.10/bdb.py", line 90, in trace_dispatch
    return self.dispatch_line(frame)
  File "/Users/kelseydoerksen/opt/anaconda3/envs/giga/lib/python3.10/bdb.py", line 115, in dispatch_line
    if self.quitting: raise BdbQuit
bdb.BdbQuit
If you suspect this is an IPython 8.7.0 bug, please report it at:
    https://github.com/ipython/ipython/issues
or send an email to the mailing list at ipython-dev@python.org
You can print a more detailed traceback right now with "%tb", or use "%debug"
to interactively debug it.
Extra-detailed tracebacks for bug-reporting purposes can be enabled via:
    %config Application.verbose_crash=True